Traceback (most recent call last):
  File "/Users/barryryan/anaconda3/lib/python3.11/site-packages/jupyter_cache/executors/utils.py", line 58, in single_nb_execution
    executenb(
  File "/Users/barryryan/anaconda3/lib/python3.11/site-packages/nbclient/client.py", line 1204, in execute
    return NotebookClient(nb=nb, resources=resources, km=km, **kwargs).execute()
           ^^^^^^^^^^^^^^^^^^^^^^^^^^^^^^^^^^^^^^^^^^^^^^^^^^^^^^^^^^^^^^^^^^^^^
  File "/Users/barryryan/anaconda3/lib/python3.11/site-packages/nbclient/util.py", line 84, in wrapped
    return just_run(coro(*args, **kwargs))
           ^^^^^^^^^^^^^^^^^^^^^^^^^^^^^^^
  File "/Users/barryryan/anaconda3/lib/python3.11/site-packages/nbclient/util.py", line 62, in just_run
    return loop.run_until_complete(coro)
           ^^^^^^^^^^^^^^^^^^^^^^^^^^^^^
  File "/Users/barryryan/anaconda3/lib/python3.11/asyncio/base_events.py", line 653, in run_until_complete
    return future.result()
           ^^^^^^^^^^^^^^^
  File "/Users/barryryan/anaconda3/lib/python3.11/site-packages/nbclient/client.py", line 663, in async_execute
    await self.async_execute_cell(
  File "/Users/barryryan/anaconda3/lib/python3.11/site-packages/nbclient/client.py", line 965, in async_execute_cell
    await self._check_raise_for_error(cell, cell_index, exec_reply)
  File "/Users/barryryan/anaconda3/lib/python3.11/site-packages/nbclient/client.py", line 862, in _check_raise_for_error
    raise CellExecutionError.from_cell_and_msg(cell, exec_reply_content)
nbclient.exceptions.CellExecutionError: An error occurred while executing the following cell:
------------------
## Load Data

with open(f'./../../data/TCGA-BRCA/{modality}/{modality}.pkl' , 'rb') as file : 
    loaded_data = pickle.load(file)
    
count_mtx = loaded_data['datExpr']
datMeta = loaded_data['datMeta'].reset_index()[['patient' , target]].set_index('patient')
------------------

[0;31m---------------------------------------------------------------------------[0m
[0;31mFileNotFoundError[0m                         Traceback (most recent call last)
Cell [0;32mIn[3], line 3[0m
[1;32m      1[0m [38;5;66;03m## Load Data[39;00m
[0;32m----> 3[0m [38;5;28;01mwith[39;00m [38;5;28mopen[39m([38;5;124mf[39m[38;5;124m'[39m[38;5;124m./../../data/TCGA-BRCA/[39m[38;5;132;01m{[39;00mmodality[38;5;132;01m}[39;00m[38;5;124m/[39m[38;5;132;01m{[39;00mmodality[38;5;132;01m}[39;00m[38;5;124m.pkl[39m[38;5;124m'[39m , [38;5;124m'[39m[38;5;124mrb[39m[38;5;124m'[39m) [38;5;28;01mas[39;00m file : 
[1;32m      4[0m     loaded_data [38;5;241m=[39m pickle[38;5;241m.[39mload(file)
[1;32m      6[0m count_mtx [38;5;241m=[39m loaded_data[[38;5;124m'[39m[38;5;124mdatExpr[39m[38;5;124m'[39m]

File [0;32m~/anaconda3/lib/python3.11/site-packages/IPython/core/interactiveshell.py:284[0m, in [0;36m_modified_open[0;34m(file, *args, **kwargs)[0m
[1;32m    277[0m [38;5;28;01mif[39;00m file [38;5;129;01min[39;00m {[38;5;241m0[39m, [38;5;241m1[39m, [38;5;241m2[39m}:
[1;32m    278[0m     [38;5;28;01mraise[39;00m [38;5;167;01mValueError[39;00m(
[1;32m    279[0m         [38;5;124mf[39m[38;5;124m"[39m[38;5;124mIPython won[39m[38;5;124m'[39m[38;5;124mt let you open fd=[39m[38;5;132;01m{[39;00mfile[38;5;132;01m}[39;00m[38;5;124m by default [39m[38;5;124m"[39m
[1;32m    280[0m         [38;5;124m"[39m[38;5;124mas it is likely to crash IPython. If you know what you are doing, [39m[38;5;124m"[39m
[1;32m    281[0m         [38;5;124m"[39m[38;5;124myou can use builtins[39m[38;5;124m'[39m[38;5;124m open.[39m[38;5;124m"[39m
[1;32m    282[0m     )
[0;32m--> 284[0m [38;5;28;01mreturn[39;00m io_open(file, [38;5;241m*[39margs, [38;5;241m*[39m[38;5;241m*[39mkwargs)

[0;31mFileNotFoundError[0m: [Errno 2] No such file or directory: './../../data/TCGA-BRCA/RPPA/RPPA.pkl'
FileNotFoundError: [Errno 2] No such file or directory: './../../data/TCGA-BRCA/RPPA/RPPA.pkl'

